2025-01-21 13:43:23,843 - INFO - RequestID: 20250121_134323_843452 - Starting document comparison for files: Screenshot_21-1-2025_123624_.jpeg and Screenshot_21-1-2025_123619_.jpeg
2025-01-21 13:43:23,845 - INFO - RequestID: 20250121_134323_843452 - Validating file types
2025-01-21 13:43:23,846 - INFO - RequestID: 20250121_134323_843452 - Processing first file: Screenshot_21-1-2025_123624_.jpeg
2025-01-21 13:43:23,968 - INFO - RequestID: 20250121_134323_843452 - Processing second file: Screenshot_21-1-2025_123619_.jpeg
2025-01-21 13:43:23,968 - INFO - RequestID: 20250121_134323_843452 - Processing images with OCR
2025-01-21 13:43:33,254 - INFO - RequestID: 20250121_134323_843452 - Comparing processed results
2025-01-21 13:43:33,254 - INFO - RequestID: 20250121_134323_843452 - Comparison completed. Status: Nothing Match
2025-01-21 13:49:19,464 - INFO - RequestID: 20250121_134919_464210 - Starting document comparison for files: file1.jpg and file2.jpg
2025-01-21 13:49:19,464 - INFO - RequestID: 20250121_134919_464210 - Validating file types
2025-01-21 13:49:19,464 - INFO - RequestID: 20250121_134919_464210 - Processing first file: file1.jpg
2025-01-21 13:49:19,483 - INFO - RequestID: 20250121_134919_464210 - Processing second file: file2.jpg
2025-01-21 13:49:19,483 - INFO - RequestID: 20250121_134919_464210 - Processing images with Gemini
2025-01-21 13:49:27,864 - INFO - RequestID: 20250121_134919_464210 - Comparing processed results
2025-01-21 13:49:27,864 - INFO - RequestID: 20250121_134919_464210 - Comparison completed. Status: Complete Match
2025-01-21 13:49:27,898 - INFO - RequestID: 20250121_134927_898595 - Starting document comparison for files: file1.jpg and file2.jpg
2025-01-21 13:49:27,898 - INFO - RequestID: 20250121_134927_898595 - Validating file types
2025-01-21 13:49:27,905 - INFO - RequestID: 20250121_134927_898595 - Processing first file: file1.jpg
2025-01-21 13:49:27,905 - INFO - RequestID: 20250121_134927_898595 - Processing second file: file2.jpg
2025-01-21 13:49:27,905 - INFO - RequestID: 20250121_134927_898595 - Processing images with Gemini
2025-01-21 13:49:34,937 - INFO - RequestID: 20250121_134927_898595 - Comparing processed results
2025-01-21 13:49:34,937 - INFO - RequestID: 20250121_134927_898595 - Comparison completed. Status: Complete Match
2025-01-21 13:49:34,989 - INFO - RequestID: 20250121_134934_989421 - Starting document comparison for files: file1.jpg and file2.jpg
2025-01-21 13:49:34,989 - INFO - RequestID: 20250121_134934_989421 - Validating file types
2025-01-21 13:49:34,989 - INFO - RequestID: 20250121_134934_989421 - Processing first file: file1.jpg
2025-01-21 13:49:34,989 - INFO - RequestID: 20250121_134934_989421 - Processing second file: file2.jpg
2025-01-21 13:49:34,989 - INFO - RequestID: 20250121_134934_989421 - Processing images with Gemini
2025-01-21 13:49:41,831 - INFO - RequestID: 20250121_134934_989421 - Comparing processed results
2025-01-21 13:49:41,831 - INFO - RequestID: 20250121_134934_989421 - Comparison completed. Status: Complete Match
2025-01-21 13:49:41,881 - INFO - RequestID: 20250121_134941_881992 - Starting document comparison for files: file1.jpg and file2.jpg
2025-01-21 13:49:41,881 - INFO - RequestID: 20250121_134941_881992 - Validating file types
2025-01-21 13:49:41,887 - INFO - RequestID: 20250121_134941_881992 - Processing first file: file1.jpg
2025-01-21 13:49:41,887 - INFO - RequestID: 20250121_134941_881992 - Processing second file: file2.jpg
2025-01-21 13:49:41,887 - INFO - RequestID: 20250121_134941_881992 - Processing images with Gemini
2025-01-21 13:49:48,604 - INFO - RequestID: 20250121_134941_881992 - Comparing processed results
2025-01-21 13:49:48,604 - INFO - RequestID: 20250121_134941_881992 - Comparison completed. Status: Complete Match
2025-01-21 13:49:48,668 - INFO - RequestID: 20250121_134948_668761 - Starting document comparison for files: file1.jpg and file2.jpg
2025-01-21 13:49:48,672 - INFO - RequestID: 20250121_134948_668761 - Validating file types
2025-01-21 13:49:48,672 - INFO - RequestID: 20250121_134948_668761 - Processing first file: file1.jpg
2025-01-21 13:49:48,672 - INFO - RequestID: 20250121_134948_668761 - Processing second file: file2.jpg
2025-01-21 13:49:48,672 - INFO - RequestID: 20250121_134948_668761 - Processing images with Gemini
2025-01-21 13:49:55,423 - INFO - RequestID: 20250121_134948_668761 - Comparing processed results
2025-01-21 13:49:55,423 - INFO - RequestID: 20250121_134948_668761 - Comparison completed. Status: Complete Match
2025-01-21 13:49:55,491 - INFO - RequestID: 20250121_134955_491976 - Starting document comparison for files: file1.jpg and file2.jpg
2025-01-21 13:49:55,491 - INFO - RequestID: 20250121_134955_491976 - Validating file types
2025-01-21 13:49:55,491 - INFO - RequestID: 20250121_134955_491976 - Processing first file: file1.jpg
2025-01-21 13:49:55,497 - INFO - RequestID: 20250121_134955_491976 - Processing second file: file2.jpg
2025-01-21 13:49:55,499 - INFO - RequestID: 20250121_134955_491976 - Processing images with Gemini
2025-01-21 13:50:01,567 - INFO - RequestID: 20250121_134955_491976 - Comparing processed results
2025-01-21 13:50:01,567 - INFO - RequestID: 20250121_134955_491976 - Comparison completed. Status: Complete Match
2025-01-21 13:50:01,622 - INFO - RequestID: 20250121_135001_622924 - Starting document comparison for files: file1.jpg and file2.jpg
2025-01-21 13:50:01,622 - INFO - RequestID: 20250121_135001_622924 - Validating file types
2025-01-21 13:50:01,622 - INFO - RequestID: 20250121_135001_622924 - Processing first file: file1.jpg
2025-01-21 13:50:01,622 - INFO - RequestID: 20250121_135001_622924 - Processing second file: file2.jpg
2025-01-21 13:50:01,622 - INFO - RequestID: 20250121_135001_622924 - Processing images with Gemini
2025-01-21 13:50:06,518 - INFO - RequestID: 20250121_135001_622924 - Comparing processed results
2025-01-21 13:50:06,532 - INFO - RequestID: 20250121_135001_622924 - Comparison completed. Status: Complete Match
2025-01-21 13:50:06,583 - INFO - RequestID: 20250121_135006_583158 - Starting document comparison for files: file1.jpg and file2.jpg
2025-01-21 13:50:06,583 - INFO - RequestID: 20250121_135006_583158 - Validating file types
2025-01-21 13:50:06,583 - INFO - RequestID: 20250121_135006_583158 - Processing first file: file1.jpg
2025-01-21 13:50:06,583 - INFO - RequestID: 20250121_135006_583158 - Processing second file: file2.jpg
2025-01-21 13:50:06,591 - INFO - RequestID: 20250121_135006_583158 - Processing images with Gemini
2025-01-21 13:50:11,328 - INFO - RequestID: 20250121_135006_583158 - Comparing processed results
2025-01-21 13:50:11,328 - INFO - RequestID: 20250121_135006_583158 - Comparison completed. Status: Complete Match
2025-01-21 13:50:11,380 - INFO - RequestID: 20250121_135011_380044 - Starting document comparison for files: file1.jpg and file2.jpg
2025-01-21 13:50:11,380 - INFO - RequestID: 20250121_135011_380044 - Validating file types
2025-01-21 13:50:11,380 - INFO - RequestID: 20250121_135011_380044 - Processing first file: file1.jpg
2025-01-21 13:50:11,388 - INFO - RequestID: 20250121_135011_380044 - Processing second file: file2.jpg
2025-01-21 13:50:11,388 - INFO - RequestID: 20250121_135011_380044 - Processing images with Gemini
2025-01-21 13:50:16,301 - INFO - RequestID: 20250121_135011_380044 - Comparing processed results
2025-01-21 13:50:16,301 - INFO - RequestID: 20250121_135011_380044 - Comparison completed. Status: Complete Match
2025-01-21 13:50:16,351 - INFO - RequestID: 20250121_135016_351843 - Starting document comparison for files: file1.jpg and file2.jpg
2025-01-21 13:50:16,351 - INFO - RequestID: 20250121_135016_351843 - Validating file types
2025-01-21 13:50:16,351 - INFO - RequestID: 20250121_135016_351843 - Processing first file: file1.jpg
2025-01-21 13:50:16,359 - INFO - RequestID: 20250121_135016_351843 - Processing second file: file2.jpg
2025-01-21 13:50:16,359 - INFO - RequestID: 20250121_135016_351843 - Processing images with Gemini
2025-01-21 13:50:17,499 - ERROR - RequestID: 20250121_135016_351843 - Error during document comparison: 500: Error processing image: 429 Resource has been exhausted (e.g. check quota).
Traceback (most recent call last):
  File "D:\Ops inovation\main.py", line 132, in process_image
    response = model.generate_content(
               ^^^^^^^^^^^^^^^^^^^^^^^
  File "C:\Users\temp\AppData\Local\Programs\Python\Python311\Lib\site-packages\google\generativeai\generative_models.py", line 331, in generate_content
    response = self._client.generate_content(
               ^^^^^^^^^^^^^^^^^^^^^^^^^^^^^^
  File "C:\Users\temp\AppData\Local\Programs\Python\Python311\Lib\site-packages\google\ai\generativelanguage_v1beta\services\generative_service\client.py", line 830, in generate_content
    response = rpc(
               ^^^^
  File "C:\Users\temp\AppData\Local\Programs\Python\Python311\Lib\site-packages\google\api_core\gapic_v1\method.py", line 131, in __call__
    return wrapped_func(*args, **kwargs)
           ^^^^^^^^^^^^^^^^^^^^^^^^^^^^^
  File "C:\Users\temp\AppData\Local\Programs\Python\Python311\Lib\site-packages\google\api_core\retry\retry_unary.py", line 293, in retry_wrapped_func
    return retry_target(
           ^^^^^^^^^^^^^
  File "C:\Users\temp\AppData\Local\Programs\Python\Python311\Lib\site-packages\google\api_core\retry\retry_unary.py", line 153, in retry_target
    _retry_error_helper(
  File "C:\Users\temp\AppData\Local\Programs\Python\Python311\Lib\site-packages\google\api_core\retry\retry_base.py", line 212, in _retry_error_helper
    raise final_exc from source_exc
  File "C:\Users\temp\AppData\Local\Programs\Python\Python311\Lib\site-packages\google\api_core\retry\retry_unary.py", line 144, in retry_target
    result = target()
             ^^^^^^^^
  File "C:\Users\temp\AppData\Local\Programs\Python\Python311\Lib\site-packages\google\api_core\timeout.py", line 120, in func_with_timeout
    return func(*args, **kwargs)
           ^^^^^^^^^^^^^^^^^^^^^
  File "C:\Users\temp\AppData\Local\Programs\Python\Python311\Lib\site-packages\google\api_core\grpc_helpers.py", line 78, in error_remapped_callable
    raise exceptions.from_grpc_error(exc) from exc
google.api_core.exceptions.ResourceExhausted: 429 Resource has been exhausted (e.g. check quota).

During handling of the above exception, another exception occurred:

Traceback (most recent call last):
  File "D:\Ops inovation\main.py", line 179, in compare_documents
    response1 = await process_image(image1, FIELDS1, MAPPING_IMG1)
                ^^^^^^^^^^^^^^^^^^^^^^^^^^^^^^^^^^^^^^^^^^^^^^^^^^
  File "D:\Ops inovation\main.py", line 138, in process_image
    raise HTTPException(status_code=500, detail=f"Error processing image: {str(e)}")
fastapi.exceptions.HTTPException: 500: Error processing image: 429 Resource has been exhausted (e.g. check quota).
2025-01-21 13:50:17,637 - INFO - RequestID: 20250121_135017_637536 - Starting document comparison for files: file1.jpg and file2.jpg
2025-01-21 13:50:17,637 - INFO - RequestID: 20250121_135017_637536 - Validating file types
2025-01-21 13:50:17,642 - INFO - RequestID: 20250121_135017_637536 - Processing first file: file1.jpg
2025-01-21 13:50:17,642 - INFO - RequestID: 20250121_135017_637536 - Processing second file: file2.jpg
2025-01-21 13:50:17,644 - INFO - RequestID: 20250121_135017_637536 - Processing images with Gemini
2025-01-21 13:50:20,943 - ERROR - RequestID: 20250121_135017_637536 - Error during document comparison: 500: Error processing image: 429 Resource has been exhausted (e.g. check quota).
Traceback (most recent call last):
  File "D:\Ops inovation\main.py", line 132, in process_image
    response = model.generate_content(
               ^^^^^^^^^^^^^^^^^^^^^^^
  File "C:\Users\temp\AppData\Local\Programs\Python\Python311\Lib\site-packages\google\generativeai\generative_models.py", line 331, in generate_content
    response = self._client.generate_content(
               ^^^^^^^^^^^^^^^^^^^^^^^^^^^^^^
  File "C:\Users\temp\AppData\Local\Programs\Python\Python311\Lib\site-packages\google\ai\generativelanguage_v1beta\services\generative_service\client.py", line 830, in generate_content
    response = rpc(
               ^^^^
  File "C:\Users\temp\AppData\Local\Programs\Python\Python311\Lib\site-packages\google\api_core\gapic_v1\method.py", line 131, in __call__
    return wrapped_func(*args, **kwargs)
           ^^^^^^^^^^^^^^^^^^^^^^^^^^^^^
  File "C:\Users\temp\AppData\Local\Programs\Python\Python311\Lib\site-packages\google\api_core\retry\retry_unary.py", line 293, in retry_wrapped_func
    return retry_target(
           ^^^^^^^^^^^^^
  File "C:\Users\temp\AppData\Local\Programs\Python\Python311\Lib\site-packages\google\api_core\retry\retry_unary.py", line 153, in retry_target
    _retry_error_helper(
  File "C:\Users\temp\AppData\Local\Programs\Python\Python311\Lib\site-packages\google\api_core\retry\retry_base.py", line 212, in _retry_error_helper
    raise final_exc from source_exc
  File "C:\Users\temp\AppData\Local\Programs\Python\Python311\Lib\site-packages\google\api_core\retry\retry_unary.py", line 144, in retry_target
    result = target()
             ^^^^^^^^
  File "C:\Users\temp\AppData\Local\Programs\Python\Python311\Lib\site-packages\google\api_core\timeout.py", line 120, in func_with_timeout
    return func(*args, **kwargs)
           ^^^^^^^^^^^^^^^^^^^^^
  File "C:\Users\temp\AppData\Local\Programs\Python\Python311\Lib\site-packages\google\api_core\grpc_helpers.py", line 78, in error_remapped_callable
    raise exceptions.from_grpc_error(exc) from exc
google.api_core.exceptions.ResourceExhausted: 429 Resource has been exhausted (e.g. check quota).

During handling of the above exception, another exception occurred:

Traceback (most recent call last):
  File "D:\Ops inovation\main.py", line 180, in compare_documents
    response2 = await process_image(image2, FIELDS2, MAPPING_IMG2)
                ^^^^^^^^^^^^^^^^^^^^^^^^^^^^^^^^^^^^^^^^^^^^^^^^^^
  File "D:\Ops inovation\main.py", line 138, in process_image
    raise HTTPException(status_code=500, detail=f"Error processing image: {str(e)}")
fastapi.exceptions.HTTPException: 500: Error processing image: 429 Resource has been exhausted (e.g. check quota).
2025-01-21 13:50:21,000 - INFO - RequestID: 20250121_135021_000070 - Starting document comparison for files: file1.jpg and file2.jpg
2025-01-21 13:50:21,000 - INFO - RequestID: 20250121_135021_000070 - Validating file types
2025-01-21 13:50:21,002 - INFO - RequestID: 20250121_135021_000070 - Processing first file: file1.jpg
2025-01-21 13:50:21,002 - INFO - RequestID: 20250121_135021_000070 - Processing second file: file2.jpg
2025-01-21 13:50:21,002 - INFO - RequestID: 20250121_135021_000070 - Processing images with Gemini
2025-01-21 13:50:22,081 - ERROR - RequestID: 20250121_135021_000070 - Error during document comparison: 500: Error processing image: 429 Resource has been exhausted (e.g. check quota).
Traceback (most recent call last):
  File "D:\Ops inovation\main.py", line 132, in process_image
    response = model.generate_content(
               ^^^^^^^^^^^^^^^^^^^^^^^
  File "C:\Users\temp\AppData\Local\Programs\Python\Python311\Lib\site-packages\google\generativeai\generative_models.py", line 331, in generate_content
    response = self._client.generate_content(
               ^^^^^^^^^^^^^^^^^^^^^^^^^^^^^^
  File "C:\Users\temp\AppData\Local\Programs\Python\Python311\Lib\site-packages\google\ai\generativelanguage_v1beta\services\generative_service\client.py", line 830, in generate_content
    response = rpc(
               ^^^^
  File "C:\Users\temp\AppData\Local\Programs\Python\Python311\Lib\site-packages\google\api_core\gapic_v1\method.py", line 131, in __call__
    return wrapped_func(*args, **kwargs)
           ^^^^^^^^^^^^^^^^^^^^^^^^^^^^^
  File "C:\Users\temp\AppData\Local\Programs\Python\Python311\Lib\site-packages\google\api_core\retry\retry_unary.py", line 293, in retry_wrapped_func
    return retry_target(
           ^^^^^^^^^^^^^
  File "C:\Users\temp\AppData\Local\Programs\Python\Python311\Lib\site-packages\google\api_core\retry\retry_unary.py", line 153, in retry_target
    _retry_error_helper(
  File "C:\Users\temp\AppData\Local\Programs\Python\Python311\Lib\site-packages\google\api_core\retry\retry_base.py", line 212, in _retry_error_helper
    raise final_exc from source_exc
  File "C:\Users\temp\AppData\Local\Programs\Python\Python311\Lib\site-packages\google\api_core\retry\retry_unary.py", line 144, in retry_target
    result = target()
             ^^^^^^^^
  File "C:\Users\temp\AppData\Local\Programs\Python\Python311\Lib\site-packages\google\api_core\timeout.py", line 120, in func_with_timeout
    return func(*args, **kwargs)
           ^^^^^^^^^^^^^^^^^^^^^
  File "C:\Users\temp\AppData\Local\Programs\Python\Python311\Lib\site-packages\google\api_core\grpc_helpers.py", line 78, in error_remapped_callable
    raise exceptions.from_grpc_error(exc) from exc
google.api_core.exceptions.ResourceExhausted: 429 Resource has been exhausted (e.g. check quota).

During handling of the above exception, another exception occurred:

Traceback (most recent call last):
  File "D:\Ops inovation\main.py", line 179, in compare_documents
    response1 = await process_image(image1, FIELDS1, MAPPING_IMG1)
                ^^^^^^^^^^^^^^^^^^^^^^^^^^^^^^^^^^^^^^^^^^^^^^^^^^
  File "D:\Ops inovation\main.py", line 138, in process_image
    raise HTTPException(status_code=500, detail=f"Error processing image: {str(e)}")
fastapi.exceptions.HTTPException: 500: Error processing image: 429 Resource has been exhausted (e.g. check quota).
2025-01-21 13:50:22,136 - INFO - RequestID: 20250121_135022_136825 - Starting document comparison for files: file1.jpg and file2.jpg
2025-01-21 13:50:22,136 - INFO - RequestID: 20250121_135022_136825 - Validating file types
2025-01-21 13:50:22,136 - INFO - RequestID: 20250121_135022_136825 - Processing first file: file1.jpg
2025-01-21 13:50:22,136 - INFO - RequestID: 20250121_135022_136825 - Processing second file: file2.jpg
2025-01-21 13:50:22,136 - INFO - RequestID: 20250121_135022_136825 - Processing images with Gemini
2025-01-21 13:50:23,144 - ERROR - RequestID: 20250121_135022_136825 - Error during document comparison: 500: Error processing image: 429 Resource has been exhausted (e.g. check quota).
Traceback (most recent call last):
  File "D:\Ops inovation\main.py", line 132, in process_image
    response = model.generate_content(
               ^^^^^^^^^^^^^^^^^^^^^^^
  File "C:\Users\temp\AppData\Local\Programs\Python\Python311\Lib\site-packages\google\generativeai\generative_models.py", line 331, in generate_content
    response = self._client.generate_content(
               ^^^^^^^^^^^^^^^^^^^^^^^^^^^^^^
  File "C:\Users\temp\AppData\Local\Programs\Python\Python311\Lib\site-packages\google\ai\generativelanguage_v1beta\services\generative_service\client.py", line 830, in generate_content
    response = rpc(
               ^^^^
  File "C:\Users\temp\AppData\Local\Programs\Python\Python311\Lib\site-packages\google\api_core\gapic_v1\method.py", line 131, in __call__
    return wrapped_func(*args, **kwargs)
           ^^^^^^^^^^^^^^^^^^^^^^^^^^^^^
  File "C:\Users\temp\AppData\Local\Programs\Python\Python311\Lib\site-packages\google\api_core\retry\retry_unary.py", line 293, in retry_wrapped_func
    return retry_target(
           ^^^^^^^^^^^^^
  File "C:\Users\temp\AppData\Local\Programs\Python\Python311\Lib\site-packages\google\api_core\retry\retry_unary.py", line 153, in retry_target
    _retry_error_helper(
  File "C:\Users\temp\AppData\Local\Programs\Python\Python311\Lib\site-packages\google\api_core\retry\retry_base.py", line 212, in _retry_error_helper
    raise final_exc from source_exc
  File "C:\Users\temp\AppData\Local\Programs\Python\Python311\Lib\site-packages\google\api_core\retry\retry_unary.py", line 144, in retry_target
    result = target()
             ^^^^^^^^
  File "C:\Users\temp\AppData\Local\Programs\Python\Python311\Lib\site-packages\google\api_core\timeout.py", line 120, in func_with_timeout
    return func(*args, **kwargs)
           ^^^^^^^^^^^^^^^^^^^^^
  File "C:\Users\temp\AppData\Local\Programs\Python\Python311\Lib\site-packages\google\api_core\grpc_helpers.py", line 78, in error_remapped_callable
    raise exceptions.from_grpc_error(exc) from exc
google.api_core.exceptions.ResourceExhausted: 429 Resource has been exhausted (e.g. check quota).

During handling of the above exception, another exception occurred:

Traceback (most recent call last):
  File "D:\Ops inovation\main.py", line 179, in compare_documents
    response1 = await process_image(image1, FIELDS1, MAPPING_IMG1)
                ^^^^^^^^^^^^^^^^^^^^^^^^^^^^^^^^^^^^^^^^^^^^^^^^^^
  File "D:\Ops inovation\main.py", line 138, in process_image
    raise HTTPException(status_code=500, detail=f"Error processing image: {str(e)}")
fastapi.exceptions.HTTPException: 500: Error processing image: 429 Resource has been exhausted (e.g. check quota).
2025-01-21 13:50:23,199 - INFO - RequestID: 20250121_135023_199718 - Starting document comparison for files: file1.jpg and file2.jpg
2025-01-21 13:50:23,199 - INFO - RequestID: 20250121_135023_199718 - Validating file types
2025-01-21 13:50:23,199 - INFO - RequestID: 20250121_135023_199718 - Processing first file: file1.jpg
2025-01-21 13:50:23,204 - INFO - RequestID: 20250121_135023_199718 - Processing second file: file2.jpg
2025-01-21 13:50:23,204 - INFO - RequestID: 20250121_135023_199718 - Processing images with Gemini
2025-01-21 13:50:24,410 - ERROR - RequestID: 20250121_135023_199718 - Error during document comparison: 500: Error processing image: 429 Resource has been exhausted (e.g. check quota).
Traceback (most recent call last):
  File "D:\Ops inovation\main.py", line 132, in process_image
    response = model.generate_content(
               ^^^^^^^^^^^^^^^^^^^^^^^
  File "C:\Users\temp\AppData\Local\Programs\Python\Python311\Lib\site-packages\google\generativeai\generative_models.py", line 331, in generate_content
    response = self._client.generate_content(
               ^^^^^^^^^^^^^^^^^^^^^^^^^^^^^^
  File "C:\Users\temp\AppData\Local\Programs\Python\Python311\Lib\site-packages\google\ai\generativelanguage_v1beta\services\generative_service\client.py", line 830, in generate_content
    response = rpc(
               ^^^^
  File "C:\Users\temp\AppData\Local\Programs\Python\Python311\Lib\site-packages\google\api_core\gapic_v1\method.py", line 131, in __call__
    return wrapped_func(*args, **kwargs)
           ^^^^^^^^^^^^^^^^^^^^^^^^^^^^^
  File "C:\Users\temp\AppData\Local\Programs\Python\Python311\Lib\site-packages\google\api_core\retry\retry_unary.py", line 293, in retry_wrapped_func
    return retry_target(
           ^^^^^^^^^^^^^
  File "C:\Users\temp\AppData\Local\Programs\Python\Python311\Lib\site-packages\google\api_core\retry\retry_unary.py", line 153, in retry_target
    _retry_error_helper(
  File "C:\Users\temp\AppData\Local\Programs\Python\Python311\Lib\site-packages\google\api_core\retry\retry_base.py", line 212, in _retry_error_helper
    raise final_exc from source_exc
  File "C:\Users\temp\AppData\Local\Programs\Python\Python311\Lib\site-packages\google\api_core\retry\retry_unary.py", line 144, in retry_target
    result = target()
             ^^^^^^^^
  File "C:\Users\temp\AppData\Local\Programs\Python\Python311\Lib\site-packages\google\api_core\timeout.py", line 120, in func_with_timeout
    return func(*args, **kwargs)
           ^^^^^^^^^^^^^^^^^^^^^
  File "C:\Users\temp\AppData\Local\Programs\Python\Python311\Lib\site-packages\google\api_core\grpc_helpers.py", line 78, in error_remapped_callable
    raise exceptions.from_grpc_error(exc) from exc
google.api_core.exceptions.ResourceExhausted: 429 Resource has been exhausted (e.g. check quota).

During handling of the above exception, another exception occurred:

Traceback (most recent call last):
  File "D:\Ops inovation\main.py", line 179, in compare_documents
    response1 = await process_image(image1, FIELDS1, MAPPING_IMG1)
                ^^^^^^^^^^^^^^^^^^^^^^^^^^^^^^^^^^^^^^^^^^^^^^^^^^
  File "D:\Ops inovation\main.py", line 138, in process_image
    raise HTTPException(status_code=500, detail=f"Error processing image: {str(e)}")
fastapi.exceptions.HTTPException: 500: Error processing image: 429 Resource has been exhausted (e.g. check quota).
2025-01-21 13:50:24,458 - INFO - RequestID: 20250121_135024_458244 - Starting document comparison for files: file1.jpg and file2.jpg
2025-01-21 13:50:24,466 - INFO - RequestID: 20250121_135024_458244 - Validating file types
2025-01-21 13:50:24,466 - INFO - RequestID: 20250121_135024_458244 - Processing first file: file1.jpg
2025-01-21 13:50:24,466 - INFO - RequestID: 20250121_135024_458244 - Processing second file: file2.jpg
2025-01-21 13:50:24,466 - INFO - RequestID: 20250121_135024_458244 - Processing images with Gemini
2025-01-21 13:50:25,467 - ERROR - RequestID: 20250121_135024_458244 - Error during document comparison: 500: Error processing image: 429 Resource has been exhausted (e.g. check quota).
Traceback (most recent call last):
  File "D:\Ops inovation\main.py", line 132, in process_image
    response = model.generate_content(
               ^^^^^^^^^^^^^^^^^^^^^^^
  File "C:\Users\temp\AppData\Local\Programs\Python\Python311\Lib\site-packages\google\generativeai\generative_models.py", line 331, in generate_content
    response = self._client.generate_content(
               ^^^^^^^^^^^^^^^^^^^^^^^^^^^^^^
  File "C:\Users\temp\AppData\Local\Programs\Python\Python311\Lib\site-packages\google\ai\generativelanguage_v1beta\services\generative_service\client.py", line 830, in generate_content
    response = rpc(
               ^^^^
  File "C:\Users\temp\AppData\Local\Programs\Python\Python311\Lib\site-packages\google\api_core\gapic_v1\method.py", line 131, in __call__
    return wrapped_func(*args, **kwargs)
           ^^^^^^^^^^^^^^^^^^^^^^^^^^^^^
  File "C:\Users\temp\AppData\Local\Programs\Python\Python311\Lib\site-packages\google\api_core\retry\retry_unary.py", line 293, in retry_wrapped_func
    return retry_target(
           ^^^^^^^^^^^^^
  File "C:\Users\temp\AppData\Local\Programs\Python\Python311\Lib\site-packages\google\api_core\retry\retry_unary.py", line 153, in retry_target
    _retry_error_helper(
  File "C:\Users\temp\AppData\Local\Programs\Python\Python311\Lib\site-packages\google\api_core\retry\retry_base.py", line 212, in _retry_error_helper
    raise final_exc from source_exc
  File "C:\Users\temp\AppData\Local\Programs\Python\Python311\Lib\site-packages\google\api_core\retry\retry_unary.py", line 144, in retry_target
    result = target()
             ^^^^^^^^
  File "C:\Users\temp\AppData\Local\Programs\Python\Python311\Lib\site-packages\google\api_core\timeout.py", line 120, in func_with_timeout
    return func(*args, **kwargs)
           ^^^^^^^^^^^^^^^^^^^^^
  File "C:\Users\temp\AppData\Local\Programs\Python\Python311\Lib\site-packages\google\api_core\grpc_helpers.py", line 78, in error_remapped_callable
    raise exceptions.from_grpc_error(exc) from exc
google.api_core.exceptions.ResourceExhausted: 429 Resource has been exhausted (e.g. check quota).

During handling of the above exception, another exception occurred:

Traceback (most recent call last):
  File "D:\Ops inovation\main.py", line 179, in compare_documents
    response1 = await process_image(image1, FIELDS1, MAPPING_IMG1)
                ^^^^^^^^^^^^^^^^^^^^^^^^^^^^^^^^^^^^^^^^^^^^^^^^^^
  File "D:\Ops inovation\main.py", line 138, in process_image
    raise HTTPException(status_code=500, detail=f"Error processing image: {str(e)}")
fastapi.exceptions.HTTPException: 500: Error processing image: 429 Resource has been exhausted (e.g. check quota).
2025-01-21 13:50:25,517 - INFO - RequestID: 20250121_135025_517057 - Starting document comparison for files: file1.jpg and file2.jpg
2025-01-21 13:50:25,525 - INFO - RequestID: 20250121_135025_517057 - Validating file types
2025-01-21 13:50:25,525 - INFO - RequestID: 20250121_135025_517057 - Processing first file: file1.jpg
2025-01-21 13:50:25,525 - INFO - RequestID: 20250121_135025_517057 - Processing second file: file2.jpg
2025-01-21 13:50:25,525 - INFO - RequestID: 20250121_135025_517057 - Processing images with Gemini
2025-01-21 13:50:26,534 - ERROR - RequestID: 20250121_135025_517057 - Error during document comparison: 500: Error processing image: 429 Resource has been exhausted (e.g. check quota).
Traceback (most recent call last):
  File "D:\Ops inovation\main.py", line 132, in process_image
    response = model.generate_content(
               ^^^^^^^^^^^^^^^^^^^^^^^
  File "C:\Users\temp\AppData\Local\Programs\Python\Python311\Lib\site-packages\google\generativeai\generative_models.py", line 331, in generate_content
    response = self._client.generate_content(
               ^^^^^^^^^^^^^^^^^^^^^^^^^^^^^^
  File "C:\Users\temp\AppData\Local\Programs\Python\Python311\Lib\site-packages\google\ai\generativelanguage_v1beta\services\generative_service\client.py", line 830, in generate_content
    response = rpc(
               ^^^^
  File "C:\Users\temp\AppData\Local\Programs\Python\Python311\Lib\site-packages\google\api_core\gapic_v1\method.py", line 131, in __call__
    return wrapped_func(*args, **kwargs)
           ^^^^^^^^^^^^^^^^^^^^^^^^^^^^^
  File "C:\Users\temp\AppData\Local\Programs\Python\Python311\Lib\site-packages\google\api_core\retry\retry_unary.py", line 293, in retry_wrapped_func
    return retry_target(
           ^^^^^^^^^^^^^
  File "C:\Users\temp\AppData\Local\Programs\Python\Python311\Lib\site-packages\google\api_core\retry\retry_unary.py", line 153, in retry_target
    _retry_error_helper(
  File "C:\Users\temp\AppData\Local\Programs\Python\Python311\Lib\site-packages\google\api_core\retry\retry_base.py", line 212, in _retry_error_helper
    raise final_exc from source_exc
  File "C:\Users\temp\AppData\Local\Programs\Python\Python311\Lib\site-packages\google\api_core\retry\retry_unary.py", line 144, in retry_target
    result = target()
             ^^^^^^^^
  File "C:\Users\temp\AppData\Local\Programs\Python\Python311\Lib\site-packages\google\api_core\timeout.py", line 120, in func_with_timeout
    return func(*args, **kwargs)
           ^^^^^^^^^^^^^^^^^^^^^
  File "C:\Users\temp\AppData\Local\Programs\Python\Python311\Lib\site-packages\google\api_core\grpc_helpers.py", line 78, in error_remapped_callable
    raise exceptions.from_grpc_error(exc) from exc
google.api_core.exceptions.ResourceExhausted: 429 Resource has been exhausted (e.g. check quota).

During handling of the above exception, another exception occurred:

Traceback (most recent call last):
  File "D:\Ops inovation\main.py", line 179, in compare_documents
    response1 = await process_image(image1, FIELDS1, MAPPING_IMG1)
                ^^^^^^^^^^^^^^^^^^^^^^^^^^^^^^^^^^^^^^^^^^^^^^^^^^
  File "D:\Ops inovation\main.py", line 138, in process_image
    raise HTTPException(status_code=500, detail=f"Error processing image: {str(e)}")
fastapi.exceptions.HTTPException: 500: Error processing image: 429 Resource has been exhausted (e.g. check quota).
2025-01-21 13:50:26,582 - INFO - RequestID: 20250121_135026_582884 - Starting document comparison for files: file1.jpg and file2.jpg
2025-01-21 13:50:26,582 - INFO - RequestID: 20250121_135026_582884 - Validating file types
2025-01-21 13:50:26,587 - INFO - RequestID: 20250121_135026_582884 - Processing first file: file1.jpg
2025-01-21 13:50:26,587 - INFO - RequestID: 20250121_135026_582884 - Processing second file: file2.jpg
2025-01-21 13:50:26,587 - INFO - RequestID: 20250121_135026_582884 - Processing images with Gemini
2025-01-21 13:50:27,689 - ERROR - RequestID: 20250121_135026_582884 - Error during document comparison: 500: Error processing image: 429 Resource has been exhausted (e.g. check quota).
Traceback (most recent call last):
  File "D:\Ops inovation\main.py", line 132, in process_image
    response = model.generate_content(
               ^^^^^^^^^^^^^^^^^^^^^^^
  File "C:\Users\temp\AppData\Local\Programs\Python\Python311\Lib\site-packages\google\generativeai\generative_models.py", line 331, in generate_content
    response = self._client.generate_content(
               ^^^^^^^^^^^^^^^^^^^^^^^^^^^^^^
  File "C:\Users\temp\AppData\Local\Programs\Python\Python311\Lib\site-packages\google\ai\generativelanguage_v1beta\services\generative_service\client.py", line 830, in generate_content
    response = rpc(
               ^^^^
  File "C:\Users\temp\AppData\Local\Programs\Python\Python311\Lib\site-packages\google\api_core\gapic_v1\method.py", line 131, in __call__
    return wrapped_func(*args, **kwargs)
           ^^^^^^^^^^^^^^^^^^^^^^^^^^^^^
  File "C:\Users\temp\AppData\Local\Programs\Python\Python311\Lib\site-packages\google\api_core\retry\retry_unary.py", line 293, in retry_wrapped_func
    return retry_target(
           ^^^^^^^^^^^^^
  File "C:\Users\temp\AppData\Local\Programs\Python\Python311\Lib\site-packages\google\api_core\retry\retry_unary.py", line 153, in retry_target
    _retry_error_helper(
  File "C:\Users\temp\AppData\Local\Programs\Python\Python311\Lib\site-packages\google\api_core\retry\retry_base.py", line 212, in _retry_error_helper
    raise final_exc from source_exc
  File "C:\Users\temp\AppData\Local\Programs\Python\Python311\Lib\site-packages\google\api_core\retry\retry_unary.py", line 144, in retry_target
    result = target()
             ^^^^^^^^
  File "C:\Users\temp\AppData\Local\Programs\Python\Python311\Lib\site-packages\google\api_core\timeout.py", line 120, in func_with_timeout
    return func(*args, **kwargs)
           ^^^^^^^^^^^^^^^^^^^^^
  File "C:\Users\temp\AppData\Local\Programs\Python\Python311\Lib\site-packages\google\api_core\grpc_helpers.py", line 78, in error_remapped_callable
    raise exceptions.from_grpc_error(exc) from exc
google.api_core.exceptions.ResourceExhausted: 429 Resource has been exhausted (e.g. check quota).

During handling of the above exception, another exception occurred:

Traceback (most recent call last):
  File "D:\Ops inovation\main.py", line 179, in compare_documents
    response1 = await process_image(image1, FIELDS1, MAPPING_IMG1)
                ^^^^^^^^^^^^^^^^^^^^^^^^^^^^^^^^^^^^^^^^^^^^^^^^^^
  File "D:\Ops inovation\main.py", line 138, in process_image
    raise HTTPException(status_code=500, detail=f"Error processing image: {str(e)}")
fastapi.exceptions.HTTPException: 500: Error processing image: 429 Resource has been exhausted (e.g. check quota).
2025-01-21 13:50:27,742 - INFO - RequestID: 20250121_135027_742850 - Starting document comparison for files: file1.jpg and file2.jpg
2025-01-21 13:50:27,742 - INFO - RequestID: 20250121_135027_742850 - Validating file types
2025-01-21 13:50:27,742 - INFO - RequestID: 20250121_135027_742850 - Processing first file: file1.jpg
2025-01-21 13:50:27,751 - INFO - RequestID: 20250121_135027_742850 - Processing second file: file2.jpg
2025-01-21 13:50:27,751 - INFO - RequestID: 20250121_135027_742850 - Processing images with Gemini
2025-01-21 13:50:32,282 - INFO - RequestID: 20250121_135027_742850 - Comparing processed results
2025-01-21 13:50:32,282 - INFO - RequestID: 20250121_135027_742850 - Comparison completed. Status: Complete Match
2025-01-21 13:50:32,365 - INFO - RequestID: 20250121_135032_365317 - Starting document comparison for files: file1.jpg and file2.jpg
2025-01-21 13:50:32,370 - INFO - RequestID: 20250121_135032_365317 - Validating file types
2025-01-21 13:50:32,370 - INFO - RequestID: 20250121_135032_365317 - Processing first file: file1.jpg
2025-01-21 13:50:32,371 - INFO - RequestID: 20250121_135032_365317 - Processing second file: file2.jpg
2025-01-21 13:50:32,371 - INFO - RequestID: 20250121_135032_365317 - Processing images with Gemini
2025-01-21 13:50:37,196 - INFO - RequestID: 20250121_135032_365317 - Comparing processed results
2025-01-21 13:50:37,196 - INFO - RequestID: 20250121_135032_365317 - Comparison completed. Status: Complete Match
2025-01-21 13:50:37,251 - INFO - RequestID: 20250121_135037_251248 - Starting document comparison for files: file1.jpg and file2.jpg
2025-01-21 13:50:37,251 - INFO - RequestID: 20250121_135037_251248 - Validating file types
2025-01-21 13:50:37,253 - INFO - RequestID: 20250121_135037_251248 - Processing first file: file1.jpg
2025-01-21 13:50:37,253 - INFO - RequestID: 20250121_135037_251248 - Processing second file: file2.jpg
2025-01-21 13:50:37,253 - INFO - RequestID: 20250121_135037_251248 - Processing images with Gemini
2025-01-21 13:50:42,114 - INFO - RequestID: 20250121_135037_251248 - Comparing processed results
2025-01-21 13:50:42,114 - INFO - RequestID: 20250121_135037_251248 - Comparison completed. Status: Complete Match
2025-01-21 13:50:42,158 - INFO - RequestID: 20250121_135042_158096 - Starting document comparison for files: file1.jpg and file2.jpg
2025-01-21 13:50:42,158 - INFO - RequestID: 20250121_135042_158096 - Validating file types
2025-01-21 13:50:42,158 - INFO - RequestID: 20250121_135042_158096 - Processing first file: file1.jpg
2025-01-21 13:50:42,166 - INFO - RequestID: 20250121_135042_158096 - Processing second file: file2.jpg
2025-01-21 13:50:42,166 - INFO - RequestID: 20250121_135042_158096 - Processing images with Gemini
2025-01-21 13:50:46,752 - INFO - RequestID: 20250121_135042_158096 - Comparing processed results
2025-01-21 13:50:46,752 - INFO - RequestID: 20250121_135042_158096 - Comparison completed. Status: Complete Match
2025-01-21 13:50:46,801 - INFO - RequestID: 20250121_135046_801606 - Starting document comparison for files: file1.jpg and file2.jpg
2025-01-21 13:50:46,801 - INFO - RequestID: 20250121_135046_801606 - Validating file types
2025-01-21 13:50:46,801 - INFO - RequestID: 20250121_135046_801606 - Processing first file: file1.jpg
2025-01-21 13:50:46,801 - INFO - RequestID: 20250121_135046_801606 - Processing second file: file2.jpg
2025-01-21 13:50:46,809 - INFO - RequestID: 20250121_135046_801606 - Processing images with Gemini
2025-01-21 13:50:51,580 - INFO - RequestID: 20250121_135046_801606 - Comparing processed results
2025-01-21 13:50:51,580 - INFO - RequestID: 20250121_135046_801606 - Comparison completed. Status: Complete Match
2025-01-21 13:50:51,623 - INFO - RequestID: 20250121_135051_623163 - Starting document comparison for files: file1.jpg and file2.jpg
2025-01-21 13:50:51,623 - INFO - RequestID: 20250121_135051_623163 - Validating file types
2025-01-21 13:50:51,628 - INFO - RequestID: 20250121_135051_623163 - Processing first file: file1.jpg
2025-01-21 13:50:51,628 - INFO - RequestID: 20250121_135051_623163 - Processing second file: file2.jpg
2025-01-21 13:50:51,628 - INFO - RequestID: 20250121_135051_623163 - Processing images with Gemini
2025-01-21 13:50:56,332 - INFO - RequestID: 20250121_135051_623163 - Comparing processed results
2025-01-21 13:50:56,332 - INFO - RequestID: 20250121_135051_623163 - Comparison completed. Status: Complete Match
2025-01-21 13:50:56,376 - INFO - RequestID: 20250121_135056_376535 - Starting document comparison for files: file1.jpg and file2.jpg
2025-01-21 13:50:56,376 - INFO - RequestID: 20250121_135056_376535 - Validating file types
2025-01-21 13:50:56,376 - INFO - RequestID: 20250121_135056_376535 - Processing first file: file1.jpg
2025-01-21 13:50:56,376 - INFO - RequestID: 20250121_135056_376535 - Processing second file: file2.jpg
2025-01-21 13:50:56,384 - INFO - RequestID: 20250121_135056_376535 - Processing images with Gemini
2025-01-21 13:51:00,891 - INFO - RequestID: 20250121_135056_376535 - Comparing processed results
2025-01-21 13:51:00,891 - INFO - RequestID: 20250121_135056_376535 - Comparison completed. Status: Complete Match
2025-01-21 13:51:00,952 - INFO - RequestID: 20250121_135100_952215 - Starting document comparison for files: file1.jpg and file2.jpg
2025-01-21 13:51:00,952 - INFO - RequestID: 20250121_135100_952215 - Validating file types
2025-01-21 13:51:00,954 - INFO - RequestID: 20250121_135100_952215 - Processing first file: file1.jpg
2025-01-21 13:51:00,954 - INFO - RequestID: 20250121_135100_952215 - Processing second file: file2.jpg
2025-01-21 13:51:00,954 - INFO - RequestID: 20250121_135100_952215 - Processing images with Gemini
2025-01-21 13:51:04,186 - ERROR - RequestID: 20250121_135100_952215 - Error during document comparison: 500: Error processing image: 429 Resource has been exhausted (e.g. check quota).
Traceback (most recent call last):
  File "D:\Ops inovation\main.py", line 132, in process_image
    response = model.generate_content(
               ^^^^^^^^^^^^^^^^^^^^^^^
  File "C:\Users\temp\AppData\Local\Programs\Python\Python311\Lib\site-packages\google\generativeai\generative_models.py", line 331, in generate_content
    response = self._client.generate_content(
               ^^^^^^^^^^^^^^^^^^^^^^^^^^^^^^
  File "C:\Users\temp\AppData\Local\Programs\Python\Python311\Lib\site-packages\google\ai\generativelanguage_v1beta\services\generative_service\client.py", line 830, in generate_content
    response = rpc(
               ^^^^
  File "C:\Users\temp\AppData\Local\Programs\Python\Python311\Lib\site-packages\google\api_core\gapic_v1\method.py", line 131, in __call__
    return wrapped_func(*args, **kwargs)
           ^^^^^^^^^^^^^^^^^^^^^^^^^^^^^
  File "C:\Users\temp\AppData\Local\Programs\Python\Python311\Lib\site-packages\google\api_core\retry\retry_unary.py", line 293, in retry_wrapped_func
    return retry_target(
           ^^^^^^^^^^^^^
  File "C:\Users\temp\AppData\Local\Programs\Python\Python311\Lib\site-packages\google\api_core\retry\retry_unary.py", line 153, in retry_target
    _retry_error_helper(
  File "C:\Users\temp\AppData\Local\Programs\Python\Python311\Lib\site-packages\google\api_core\retry\retry_base.py", line 212, in _retry_error_helper
    raise final_exc from source_exc
  File "C:\Users\temp\AppData\Local\Programs\Python\Python311\Lib\site-packages\google\api_core\retry\retry_unary.py", line 144, in retry_target
    result = target()
             ^^^^^^^^
  File "C:\Users\temp\AppData\Local\Programs\Python\Python311\Lib\site-packages\google\api_core\timeout.py", line 120, in func_with_timeout
    return func(*args, **kwargs)
           ^^^^^^^^^^^^^^^^^^^^^
  File "C:\Users\temp\AppData\Local\Programs\Python\Python311\Lib\site-packages\google\api_core\grpc_helpers.py", line 78, in error_remapped_callable
    raise exceptions.from_grpc_error(exc) from exc
google.api_core.exceptions.ResourceExhausted: 429 Resource has been exhausted (e.g. check quota).

During handling of the above exception, another exception occurred:

Traceback (most recent call last):
  File "D:\Ops inovation\main.py", line 180, in compare_documents
    response2 = await process_image(image2, FIELDS2, MAPPING_IMG2)
                ^^^^^^^^^^^^^^^^^^^^^^^^^^^^^^^^^^^^^^^^^^^^^^^^^^
  File "D:\Ops inovation\main.py", line 138, in process_image
    raise HTTPException(status_code=500, detail=f"Error processing image: {str(e)}")
fastapi.exceptions.HTTPException: 500: Error processing image: 429 Resource has been exhausted (e.g. check quota).
2025-01-21 13:51:04,230 - INFO - RequestID: 20250121_135104_230846 - Starting document comparison for files: file1.jpg and file2.jpg
2025-01-21 13:51:04,238 - INFO - RequestID: 20250121_135104_230846 - Validating file types
2025-01-21 13:51:04,239 - INFO - RequestID: 20250121_135104_230846 - Processing first file: file1.jpg
2025-01-21 13:51:04,239 - INFO - RequestID: 20250121_135104_230846 - Processing second file: file2.jpg
2025-01-21 13:51:04,239 - INFO - RequestID: 20250121_135104_230846 - Processing images with Gemini
2025-01-21 13:51:05,305 - ERROR - RequestID: 20250121_135104_230846 - Error during document comparison: 500: Error processing image: 429 Resource has been exhausted (e.g. check quota).
Traceback (most recent call last):
  File "D:\Ops inovation\main.py", line 132, in process_image
    response = model.generate_content(
               ^^^^^^^^^^^^^^^^^^^^^^^
  File "C:\Users\temp\AppData\Local\Programs\Python\Python311\Lib\site-packages\google\generativeai\generative_models.py", line 331, in generate_content
    response = self._client.generate_content(
               ^^^^^^^^^^^^^^^^^^^^^^^^^^^^^^
  File "C:\Users\temp\AppData\Local\Programs\Python\Python311\Lib\site-packages\google\ai\generativelanguage_v1beta\services\generative_service\client.py", line 830, in generate_content
    response = rpc(
               ^^^^
  File "C:\Users\temp\AppData\Local\Programs\Python\Python311\Lib\site-packages\google\api_core\gapic_v1\method.py", line 131, in __call__
    return wrapped_func(*args, **kwargs)
           ^^^^^^^^^^^^^^^^^^^^^^^^^^^^^
  File "C:\Users\temp\AppData\Local\Programs\Python\Python311\Lib\site-packages\google\api_core\retry\retry_unary.py", line 293, in retry_wrapped_func
    return retry_target(
           ^^^^^^^^^^^^^
  File "C:\Users\temp\AppData\Local\Programs\Python\Python311\Lib\site-packages\google\api_core\retry\retry_unary.py", line 153, in retry_target
    _retry_error_helper(
  File "C:\Users\temp\AppData\Local\Programs\Python\Python311\Lib\site-packages\google\api_core\retry\retry_base.py", line 212, in _retry_error_helper
    raise final_exc from source_exc
  File "C:\Users\temp\AppData\Local\Programs\Python\Python311\Lib\site-packages\google\api_core\retry\retry_unary.py", line 144, in retry_target
    result = target()
             ^^^^^^^^
  File "C:\Users\temp\AppData\Local\Programs\Python\Python311\Lib\site-packages\google\api_core\timeout.py", line 120, in func_with_timeout
    return func(*args, **kwargs)
           ^^^^^^^^^^^^^^^^^^^^^
  File "C:\Users\temp\AppData\Local\Programs\Python\Python311\Lib\site-packages\google\api_core\grpc_helpers.py", line 78, in error_remapped_callable
    raise exceptions.from_grpc_error(exc) from exc
google.api_core.exceptions.ResourceExhausted: 429 Resource has been exhausted (e.g. check quota).

During handling of the above exception, another exception occurred:

Traceback (most recent call last):
  File "D:\Ops inovation\main.py", line 179, in compare_documents
    response1 = await process_image(image1, FIELDS1, MAPPING_IMG1)
                ^^^^^^^^^^^^^^^^^^^^^^^^^^^^^^^^^^^^^^^^^^^^^^^^^^
  File "D:\Ops inovation\main.py", line 138, in process_image
    raise HTTPException(status_code=500, detail=f"Error processing image: {str(e)}")
fastapi.exceptions.HTTPException: 500: Error processing image: 429 Resource has been exhausted (e.g. check quota).
2025-01-21 13:51:05,356 - INFO - RequestID: 20250121_135105_356289 - Starting document comparison for files: file1.jpg and file2.jpg
2025-01-21 13:51:05,356 - INFO - RequestID: 20250121_135105_356289 - Validating file types
2025-01-21 13:51:05,363 - INFO - RequestID: 20250121_135105_356289 - Processing first file: file1.jpg
2025-01-21 13:51:05,364 - INFO - RequestID: 20250121_135105_356289 - Processing second file: file2.jpg
2025-01-21 13:51:05,364 - INFO - RequestID: 20250121_135105_356289 - Processing images with Gemini
2025-01-21 13:51:06,372 - ERROR - RequestID: 20250121_135105_356289 - Error during document comparison: 500: Error processing image: 429 Resource has been exhausted (e.g. check quota).
Traceback (most recent call last):
  File "D:\Ops inovation\main.py", line 132, in process_image
    response = model.generate_content(
               ^^^^^^^^^^^^^^^^^^^^^^^
  File "C:\Users\temp\AppData\Local\Programs\Python\Python311\Lib\site-packages\google\generativeai\generative_models.py", line 331, in generate_content
    response = self._client.generate_content(
               ^^^^^^^^^^^^^^^^^^^^^^^^^^^^^^
  File "C:\Users\temp\AppData\Local\Programs\Python\Python311\Lib\site-packages\google\ai\generativelanguage_v1beta\services\generative_service\client.py", line 830, in generate_content
    response = rpc(
               ^^^^
  File "C:\Users\temp\AppData\Local\Programs\Python\Python311\Lib\site-packages\google\api_core\gapic_v1\method.py", line 131, in __call__
    return wrapped_func(*args, **kwargs)
           ^^^^^^^^^^^^^^^^^^^^^^^^^^^^^
  File "C:\Users\temp\AppData\Local\Programs\Python\Python311\Lib\site-packages\google\api_core\retry\retry_unary.py", line 293, in retry_wrapped_func
    return retry_target(
           ^^^^^^^^^^^^^
  File "C:\Users\temp\AppData\Local\Programs\Python\Python311\Lib\site-packages\google\api_core\retry\retry_unary.py", line 153, in retry_target
    _retry_error_helper(
  File "C:\Users\temp\AppData\Local\Programs\Python\Python311\Lib\site-packages\google\api_core\retry\retry_base.py", line 212, in _retry_error_helper
    raise final_exc from source_exc
  File "C:\Users\temp\AppData\Local\Programs\Python\Python311\Lib\site-packages\google\api_core\retry\retry_unary.py", line 144, in retry_target
    result = target()
             ^^^^^^^^
  File "C:\Users\temp\AppData\Local\Programs\Python\Python311\Lib\site-packages\google\api_core\timeout.py", line 120, in func_with_timeout
    return func(*args, **kwargs)
           ^^^^^^^^^^^^^^^^^^^^^
  File "C:\Users\temp\AppData\Local\Programs\Python\Python311\Lib\site-packages\google\api_core\grpc_helpers.py", line 78, in error_remapped_callable
    raise exceptions.from_grpc_error(exc) from exc
google.api_core.exceptions.ResourceExhausted: 429 Resource has been exhausted (e.g. check quota).

During handling of the above exception, another exception occurred:

Traceback (most recent call last):
  File "D:\Ops inovation\main.py", line 179, in compare_documents
    response1 = await process_image(image1, FIELDS1, MAPPING_IMG1)
                ^^^^^^^^^^^^^^^^^^^^^^^^^^^^^^^^^^^^^^^^^^^^^^^^^^
  File "D:\Ops inovation\main.py", line 138, in process_image
    raise HTTPException(status_code=500, detail=f"Error processing image: {str(e)}")
fastapi.exceptions.HTTPException: 500: Error processing image: 429 Resource has been exhausted (e.g. check quota).
2025-01-21 13:51:06,425 - INFO - RequestID: 20250121_135106_425032 - Starting document comparison for files: file1.jpg and file2.jpg
2025-01-21 13:51:06,425 - INFO - RequestID: 20250121_135106_425032 - Validating file types
2025-01-21 13:51:06,425 - INFO - RequestID: 20250121_135106_425032 - Processing first file: file1.jpg
2025-01-21 13:51:06,433 - INFO - RequestID: 20250121_135106_425032 - Processing second file: file2.jpg
2025-01-21 13:51:06,433 - INFO - RequestID: 20250121_135106_425032 - Processing images with Gemini
2025-01-21 13:51:07,469 - ERROR - RequestID: 20250121_135106_425032 - Error during document comparison: 500: Error processing image: 429 Resource has been exhausted (e.g. check quota).
Traceback (most recent call last):
  File "D:\Ops inovation\main.py", line 132, in process_image
    response = model.generate_content(
               ^^^^^^^^^^^^^^^^^^^^^^^
  File "C:\Users\temp\AppData\Local\Programs\Python\Python311\Lib\site-packages\google\generativeai\generative_models.py", line 331, in generate_content
    response = self._client.generate_content(
               ^^^^^^^^^^^^^^^^^^^^^^^^^^^^^^
  File "C:\Users\temp\AppData\Local\Programs\Python\Python311\Lib\site-packages\google\ai\generativelanguage_v1beta\services\generative_service\client.py", line 830, in generate_content
    response = rpc(
               ^^^^
  File "C:\Users\temp\AppData\Local\Programs\Python\Python311\Lib\site-packages\google\api_core\gapic_v1\method.py", line 131, in __call__
    return wrapped_func(*args, **kwargs)
           ^^^^^^^^^^^^^^^^^^^^^^^^^^^^^
  File "C:\Users\temp\AppData\Local\Programs\Python\Python311\Lib\site-packages\google\api_core\retry\retry_unary.py", line 293, in retry_wrapped_func
    return retry_target(
           ^^^^^^^^^^^^^
  File "C:\Users\temp\AppData\Local\Programs\Python\Python311\Lib\site-packages\google\api_core\retry\retry_unary.py", line 153, in retry_target
    _retry_error_helper(
  File "C:\Users\temp\AppData\Local\Programs\Python\Python311\Lib\site-packages\google\api_core\retry\retry_base.py", line 212, in _retry_error_helper
    raise final_exc from source_exc
  File "C:\Users\temp\AppData\Local\Programs\Python\Python311\Lib\site-packages\google\api_core\retry\retry_unary.py", line 144, in retry_target
    result = target()
             ^^^^^^^^
  File "C:\Users\temp\AppData\Local\Programs\Python\Python311\Lib\site-packages\google\api_core\timeout.py", line 120, in func_with_timeout
    return func(*args, **kwargs)
           ^^^^^^^^^^^^^^^^^^^^^
  File "C:\Users\temp\AppData\Local\Programs\Python\Python311\Lib\site-packages\google\api_core\grpc_helpers.py", line 78, in error_remapped_callable
    raise exceptions.from_grpc_error(exc) from exc
google.api_core.exceptions.ResourceExhausted: 429 Resource has been exhausted (e.g. check quota).

During handling of the above exception, another exception occurred:

Traceback (most recent call last):
  File "D:\Ops inovation\main.py", line 179, in compare_documents
    response1 = await process_image(image1, FIELDS1, MAPPING_IMG1)
                ^^^^^^^^^^^^^^^^^^^^^^^^^^^^^^^^^^^^^^^^^^^^^^^^^^
  File "D:\Ops inovation\main.py", line 138, in process_image
    raise HTTPException(status_code=500, detail=f"Error processing image: {str(e)}")
fastapi.exceptions.HTTPException: 500: Error processing image: 429 Resource has been exhausted (e.g. check quota).
2025-01-21 13:51:07,519 - INFO - RequestID: 20250121_135107_519881 - Starting document comparison for files: file1.jpg and file2.jpg
2025-01-21 13:51:07,519 - INFO - RequestID: 20250121_135107_519881 - Validating file types
2025-01-21 13:51:07,519 - INFO - RequestID: 20250121_135107_519881 - Processing first file: file1.jpg
2025-01-21 13:51:07,527 - INFO - RequestID: 20250121_135107_519881 - Processing second file: file2.jpg
2025-01-21 13:51:07,527 - INFO - RequestID: 20250121_135107_519881 - Processing images with Gemini
2025-01-21 13:51:08,531 - ERROR - RequestID: 20250121_135107_519881 - Error during document comparison: 500: Error processing image: 429 Resource has been exhausted (e.g. check quota).
Traceback (most recent call last):
  File "D:\Ops inovation\main.py", line 132, in process_image
    response = model.generate_content(
               ^^^^^^^^^^^^^^^^^^^^^^^
  File "C:\Users\temp\AppData\Local\Programs\Python\Python311\Lib\site-packages\google\generativeai\generative_models.py", line 331, in generate_content
    response = self._client.generate_content(
               ^^^^^^^^^^^^^^^^^^^^^^^^^^^^^^
  File "C:\Users\temp\AppData\Local\Programs\Python\Python311\Lib\site-packages\google\ai\generativelanguage_v1beta\services\generative_service\client.py", line 830, in generate_content
    response = rpc(
               ^^^^
  File "C:\Users\temp\AppData\Local\Programs\Python\Python311\Lib\site-packages\google\api_core\gapic_v1\method.py", line 131, in __call__
    return wrapped_func(*args, **kwargs)
           ^^^^^^^^^^^^^^^^^^^^^^^^^^^^^
  File "C:\Users\temp\AppData\Local\Programs\Python\Python311\Lib\site-packages\google\api_core\retry\retry_unary.py", line 293, in retry_wrapped_func
    return retry_target(
           ^^^^^^^^^^^^^
  File "C:\Users\temp\AppData\Local\Programs\Python\Python311\Lib\site-packages\google\api_core\retry\retry_unary.py", line 153, in retry_target
    _retry_error_helper(
  File "C:\Users\temp\AppData\Local\Programs\Python\Python311\Lib\site-packages\google\api_core\retry\retry_base.py", line 212, in _retry_error_helper
    raise final_exc from source_exc
  File "C:\Users\temp\AppData\Local\Programs\Python\Python311\Lib\site-packages\google\api_core\retry\retry_unary.py", line 144, in retry_target
    result = target()
             ^^^^^^^^
  File "C:\Users\temp\AppData\Local\Programs\Python\Python311\Lib\site-packages\google\api_core\timeout.py", line 120, in func_with_timeout
    return func(*args, **kwargs)
           ^^^^^^^^^^^^^^^^^^^^^
  File "C:\Users\temp\AppData\Local\Programs\Python\Python311\Lib\site-packages\google\api_core\grpc_helpers.py", line 78, in error_remapped_callable
    raise exceptions.from_grpc_error(exc) from exc
google.api_core.exceptions.ResourceExhausted: 429 Resource has been exhausted (e.g. check quota).

During handling of the above exception, another exception occurred:

Traceback (most recent call last):
  File "D:\Ops inovation\main.py", line 179, in compare_documents
    response1 = await process_image(image1, FIELDS1, MAPPING_IMG1)
                ^^^^^^^^^^^^^^^^^^^^^^^^^^^^^^^^^^^^^^^^^^^^^^^^^^
  File "D:\Ops inovation\main.py", line 138, in process_image
    raise HTTPException(status_code=500, detail=f"Error processing image: {str(e)}")
fastapi.exceptions.HTTPException: 500: Error processing image: 429 Resource has been exhausted (e.g. check quota).
2025-01-21 13:51:08,588 - INFO - RequestID: 20250121_135108_588997 - Starting document comparison for files: file1.jpg and file2.jpg
2025-01-21 13:51:08,588 - INFO - RequestID: 20250121_135108_588997 - Validating file types
2025-01-21 13:51:08,588 - INFO - RequestID: 20250121_135108_588997 - Processing first file: file1.jpg
2025-01-21 13:51:08,588 - INFO - RequestID: 20250121_135108_588997 - Processing second file: file2.jpg
2025-01-21 13:51:08,588 - INFO - RequestID: 20250121_135108_588997 - Processing images with Gemini
2025-01-21 13:51:09,714 - ERROR - RequestID: 20250121_135108_588997 - Error during document comparison: 500: Error processing image: 429 Resource has been exhausted (e.g. check quota).
Traceback (most recent call last):
  File "D:\Ops inovation\main.py", line 132, in process_image
    response = model.generate_content(
               ^^^^^^^^^^^^^^^^^^^^^^^
  File "C:\Users\temp\AppData\Local\Programs\Python\Python311\Lib\site-packages\google\generativeai\generative_models.py", line 331, in generate_content
    response = self._client.generate_content(
               ^^^^^^^^^^^^^^^^^^^^^^^^^^^^^^
  File "C:\Users\temp\AppData\Local\Programs\Python\Python311\Lib\site-packages\google\ai\generativelanguage_v1beta\services\generative_service\client.py", line 830, in generate_content
    response = rpc(
               ^^^^
  File "C:\Users\temp\AppData\Local\Programs\Python\Python311\Lib\site-packages\google\api_core\gapic_v1\method.py", line 131, in __call__
    return wrapped_func(*args, **kwargs)
           ^^^^^^^^^^^^^^^^^^^^^^^^^^^^^
  File "C:\Users\temp\AppData\Local\Programs\Python\Python311\Lib\site-packages\google\api_core\retry\retry_unary.py", line 293, in retry_wrapped_func
    return retry_target(
           ^^^^^^^^^^^^^
  File "C:\Users\temp\AppData\Local\Programs\Python\Python311\Lib\site-packages\google\api_core\retry\retry_unary.py", line 153, in retry_target
    _retry_error_helper(
  File "C:\Users\temp\AppData\Local\Programs\Python\Python311\Lib\site-packages\google\api_core\retry\retry_base.py", line 212, in _retry_error_helper
    raise final_exc from source_exc
  File "C:\Users\temp\AppData\Local\Programs\Python\Python311\Lib\site-packages\google\api_core\retry\retry_unary.py", line 144, in retry_target
    result = target()
             ^^^^^^^^
  File "C:\Users\temp\AppData\Local\Programs\Python\Python311\Lib\site-packages\google\api_core\timeout.py", line 120, in func_with_timeout
    return func(*args, **kwargs)
           ^^^^^^^^^^^^^^^^^^^^^
  File "C:\Users\temp\AppData\Local\Programs\Python\Python311\Lib\site-packages\google\api_core\grpc_helpers.py", line 78, in error_remapped_callable
    raise exceptions.from_grpc_error(exc) from exc
google.api_core.exceptions.ResourceExhausted: 429 Resource has been exhausted (e.g. check quota).

During handling of the above exception, another exception occurred:

Traceback (most recent call last):
  File "D:\Ops inovation\main.py", line 179, in compare_documents
    response1 = await process_image(image1, FIELDS1, MAPPING_IMG1)
                ^^^^^^^^^^^^^^^^^^^^^^^^^^^^^^^^^^^^^^^^^^^^^^^^^^
  File "D:\Ops inovation\main.py", line 138, in process_image
    raise HTTPException(status_code=500, detail=f"Error processing image: {str(e)}")
fastapi.exceptions.HTTPException: 500: Error processing image: 429 Resource has been exhausted (e.g. check quota).
2025-01-21 14:11:47,266 - INFO - RequestID: 20250121_141147_266213 - Starting document comparison for files: file1.jpg and file2.jpg
2025-01-21 14:11:47,266 - INFO - RequestID: 20250121_141147_266213 - Validating file types
2025-01-21 14:11:47,266 - INFO - RequestID: 20250121_141147_266213 - Processing first file: file1.jpg
2025-01-21 14:11:47,292 - INFO - RequestID: 20250121_141147_266213 - Processing second file: file2.jpg
2025-01-21 14:11:47,292 - INFO - RequestID: 20250121_141147_266213 - Processing images with Gemini
2025-01-21 14:11:55,256 - INFO - RequestID: 20250121_141147_266213 - Comparing processed results
2025-01-21 14:11:55,256 - INFO - RequestID: 20250121_141147_266213 - Comparison completed. Status: Complete Match
2025-01-21 14:11:55,300 - INFO - RequestID: 20250121_141155_300735 - Starting document comparison for files: file1.jpg and file2.jpg
2025-01-21 14:11:55,300 - INFO - RequestID: 20250121_141155_300735 - Validating file types
2025-01-21 14:11:55,304 - INFO - RequestID: 20250121_141155_300735 - Processing first file: file1.jpg
2025-01-21 14:11:55,305 - INFO - RequestID: 20250121_141155_300735 - Processing second file: file2.jpg
2025-01-21 14:11:55,305 - INFO - RequestID: 20250121_141155_300735 - Processing images with Gemini
2025-01-21 14:12:01,650 - INFO - RequestID: 20250121_141155_300735 - Comparing processed results
2025-01-21 14:12:01,650 - INFO - RequestID: 20250121_141155_300735 - Comparison completed. Status: Complete Match
2025-01-21 14:12:01,666 - INFO - RequestID: 20250121_141201_666886 - Starting document comparison for files: file1.jpg and file2.jpg
2025-01-21 14:12:01,666 - INFO - RequestID: 20250121_141201_666886 - Validating file types
2025-01-21 14:12:01,666 - INFO - RequestID: 20250121_141201_666886 - Processing first file: file1.jpg
2025-01-21 14:12:01,671 - INFO - RequestID: 20250121_141201_666886 - Processing second file: file2.jpg
2025-01-21 14:12:01,671 - INFO - RequestID: 20250121_141201_666886 - Processing images with Gemini
2025-01-21 14:12:08,022 - INFO - RequestID: 20250121_141201_666886 - Comparing processed results
2025-01-21 14:12:08,022 - INFO - RequestID: 20250121_141201_666886 - Comparison completed. Status: Complete Match
2025-01-21 14:12:08,048 - INFO - RequestID: 20250121_141208_048523 - Starting document comparison for files: file1.jpg and file2.jpg
2025-01-21 14:12:08,048 - INFO - RequestID: 20250121_141208_048523 - Validating file types
2025-01-21 14:12:08,048 - INFO - RequestID: 20250121_141208_048523 - Processing first file: file1.jpg
2025-01-21 14:12:08,048 - INFO - RequestID: 20250121_141208_048523 - Processing second file: file2.jpg
2025-01-21 14:12:08,048 - INFO - RequestID: 20250121_141208_048523 - Processing images with Gemini
2025-01-21 14:12:14,368 - INFO - RequestID: 20250121_141208_048523 - Comparing processed results
2025-01-21 14:12:14,368 - INFO - RequestID: 20250121_141208_048523 - Comparison completed. Status: Complete Match
2025-01-21 14:12:14,382 - INFO - RequestID: 20250121_141214_382206 - Starting document comparison for files: file1.jpg and file2.jpg
2025-01-21 14:12:14,382 - INFO - RequestID: 20250121_141214_382206 - Validating file types
2025-01-21 14:12:14,382 - INFO - RequestID: 20250121_141214_382206 - Processing first file: file1.jpg
2025-01-21 14:12:14,382 - INFO - RequestID: 20250121_141214_382206 - Processing second file: file2.jpg
2025-01-21 14:12:14,382 - INFO - RequestID: 20250121_141214_382206 - Processing images with Gemini
2025-01-21 14:12:20,589 - INFO - RequestID: 20250121_141214_382206 - Comparing processed results
2025-01-21 14:12:20,589 - INFO - RequestID: 20250121_141214_382206 - Comparison completed. Status: Complete Match
